File: Theory_Data.csv
Radius (m),Aspect Ratio,Pressure Drop (Pa),Pressure Gradient(Pa m^-1),Apparent Wall Shear Rate (s^-1),Volumetric Flow Rate (m^3 s^-1),Shear Thinning Index,Viscosity Consistency (Pa s^n)
0.00025,10.0,16650000.0,3330000000.0,6.200035874216361,7.608588732199723e-11,0.67,1100.0
0.00025,10.0,16650000.0,3330000000.0,6.176309748090235,7.57947239488098e-11,0.67,1100.0
0.00025,10.0,16650000.0,3330000000.0,5.959151748520547,7.312979435460516e-11,0.67,1100.0
0.00025,10.0,16650000.0,3330000000.0,5.710489603259991,7.007825072657219e-11,0.67,1100.0
0.00025,10.0,16650000.0,3330000000.0,5.68684996362035,6.97881487022542e-11,0.67,1100.0
0.00025,10.0,16650000.0,3330000000.0,5.412970384474733,6.642714060142555e-11,0.67,1100.0
0.00025,10.0,16650000.0,3330000000.0,5.12006148848456,6.28326076490278e-11,0.67,1100.0
0.00025,10.0,16650000.0,3330000000.0,4.813701147464834,5.907300063067297e-11,0.67,1100.0
0.00025,10.0,16650000.0,3330000000.0,4.789975021338708,5.878183725748554e-11,0.67,1100.0
0.00025,10.0,16650000.0,3330000000.0,4.475138180391438,5.4918207934831786e-11,0.67,1100.0
0.000375,15.0,37462500.0,3330000000.0,10.885605814016122,4.508543749463181e-10,0.67,1100.0
0.000375,15.0,37462500.0,3330000000.0,10.869765974176282,4.501983286763856e-10,0.67,1100.0
0.000375,15.0,37462500.0,3330000000.0,10.61643508434868,4.397060012911007e-10,0.67,1100.0
0.000375,15.0,37462500.0,3330000000.0,10.334370642058374,4.280236025347875e-10,0.67,1100.0
0.000375,15.0,37462500.0,3330000000.0,10.027254629991736,4.1530363085640603e-10,0.67,1100.0
0.000375,15.0,37462500.0,3330000000.0,10.011376351713459,4.1464599256316935e-10,0.67,1100.0
0.000375,15.0,37462500.0,3330000000.0,9.68265072248686,4.010310049707504e-10,0.67,1100.0
0.000375,15.0,37462500.0,3330000000.0,9.335749768047506,3.866632411867031e-10,0.67,1100.0
0.000375,15.0,37462500.0,3330000000.0,9.319909928207668,3.860071949167706e-10,0.67,1100.0
0.000375,15.0,37462500.0,3330000000.0,8.95795452044214,3.7101591359401255e-10,0.67,1100.0
0.0005,20.0,66600000.0,3330000000.0,16.429936169589546,1.6130052115416169e-09,0.67,1100.0
0.0005,20.0,66600000.0,3330000000.0,16.14596523606402,1.585126430335466e-09,0.67,1100.0
0.0005,20.0,66600000.0,3330000000.0,16.134033704532488,1.5839550549665432e-09,0.67,1100.0
0.0005,20.0,66600000.0,3330000000.0,15.823817108549077,1.5534996118739458e-09,0.67,1100.0
0.0005,20.0,66600000.0,3330000000.0,15.489842167581193,1.5207116987168273e-09,0.67,1100.0
0.0005,20.0,66600000.0,3330000000.0,15.477932257671283,1.5195424460456433e-09,0.67,1100.0
0.0005,20.0,66600000.0,3330000000.0,15.122519933637685,1.4846499227275423e-09,0.67,1100.0
0.0005,20.0,66600000.0,3330000000.0,14.747998436966686,1.4478813607727592e-09,0.67,1100.0
0.0005,20.0,66600000.0,3330000000.0,14.356574130641523,1.4094533693606463e-09,0.67,1100.0
0.0005,20.0,66600000.0,3330000000.0,14.344642599109992,1.4082819939917234e-09,0.67,1100.0
0.000625,25.0,104062500.0,3330000000.0,22.71276601510099,4.355118338363354e-09,0.67,1100.0
0.000625,25.0,104062500.0,3330000000.0,22.401477048126885,4.295429426510974e-09,0.67,1100.0
0.000625,25.0,104062500.0,3330000000.0,22.391934705784543,4.2935997052829015e-09,0.67,1100.0
0.000625,25.0,104062500.0,3330000000.0,22.056475273073993,4.229276164671276e-09,0.67,1100.0
0.000625,25.0,104062500.0,3330000000.0,21.698643820627073,4.160662843001928e-09,0.67,1100.0
0.000625,25.0,104062500.0,3330000000.0,21.320165283314786,4.0880904923939145e-09,0.67,1100.0
0.000625,25.0,104062500.0,3330000000.0,21.31060910313461,4.086258117793669e-09,0.67,1100.0
0.000625,25.0,104062500.0,3330000000.0,20.913135192429298,4.010043449955204e-09,0.67,1100.0
0.000625,25.0,104062500.0,3330000000.0,20.498327712167313,3.930505111781062e-09,0.67,1100.0
0.000625,25.0,104062500.0,3330000000.0,20.48878536982497,3.928675390552989e-09,0.67,1100.0
0.00075,30.0,149850000.0,3330000000.0,29.65349534053459,9.82538470354387e-09,0.67,1100.0
0.00075,30.0,149850000.0,3330000000.0,29.317301936653976,9.713990431469455e-09,0.67,1100.0
0.00075,30.0,149850000.0,3330000000.0,28.95864205235963,9.595152119140607e-09,0.67,1100.0
0.00075,30.0,149850000.0,3330000000.0,28.95067248279006,9.592511483153401e-09,0.67,1100.0
0.00075,30.0,149850000.0,3330000000.0,28.57088475733779,9.46667267510059e-09,0.67,1100.0
0.00075,30.0,149850000.0,3330000000.0,28.17131717030432,9.334280010674818e-09,0.67,1100.0
0.00075,30.0,149850000.0,3330000000.0,28.163357210344365,9.331642558734221e-09,0.67,1100.0
0.00075,30.0,149850000.0,3330000000.0,27.74529035626254,9.193120349936146e-09,0.67,1100.0
0.00075,30.0,149850000.0,3330000000.0,27.310014473458374,9.04889610413941e-09,0.67,1100.0
0.00025,10.0,51855555.55555555,10371111111.11111,19.597803034474715,2.405012267172091e-10,0.67,1100.0
0.00025,10.0,51855555.55555555,10371111111.11111,19.573890971050677,2.4020778155007963e-10,0.67,1100.0
0.00025,10.0,51855555.55555555,10371111111.11111,19.386461718120334,2.379076785654164e-10,0.67,1100.0
0.00025,10.0,51855555.55555555,10371111111.11111,19.186406071481947,2.3545262641780583e-10,0.67,1100.0
0.00025,10.0,51855555.55555555,10371111111.11111,19.162521777502945,2.351595220330378e-10,0.67,1100.0
0.00025,10.0,51855555.55555555,10371111111.11111,18.950518842186046,2.3255785459502592e-10,0.67,1100.0
0.00025,10.0,51855555.55555555,10371111111.11111,18.727343654694092,2.2981908299546246e-10,0.67,1100.0
0.00025,10.0,51855555.55555555,10371111111.11111,18.493700642236977,2.2695185185679894e-10,0.67,1100.0
0.00025,10.0,51855555.55555555,10371111111.11111,18.46978857881294,2.266584066896695e-10,0.67,1100.0
0.00025,10.0,51855555.55555555,10371111111.11111,18.226311635426537,2.2367049506208662e-10,0.67,1100.0
0.000375,15.0,116674999.99999999,10371111111.11111,34.247249811251066,1.4184348277062408e-09,0.67,1100.0
0.000375,15.0,116674999.99999999,10371111111.11111,34.23130123614929,1.4177742778956333e-09,0.67,1100.0
0.000375,15.0,116674999.99999999,10371111111.11111,34.00338614281954,1.408334608785834e-09,0.67,1100.0
0.000375,15.0,116674999.99999999,10371111111.11111,33.76484756987,1.3984549419078294e-09,0.67,1100.0
0.000375,15.0,116674999.99999999,10371111111.11111,33.51609015776999,1.388152036450679e-09,0.67,1100.0
0.000375,15.0,116674999.99999999,10371111111.11111,33.50012924069264,1.3874909754665293e-09,0.67,1100.0
0.000375,15.0,116674999.99999999,10371111111.11111,33.24152744181299,1.3767803403042903e-09,0.67,1100.0
0.000375,15.0,116674999.99999999,10371111111.11111,32.97349959053076,1.3656793017931894e-09,0.67,1100.0
0.000375,15.0,116674999.99999999,10371111111.11111,32.957551015428976,1.3650187519825819e-09,0.67,1100.0
0.000375,15.0,116674999.99999999,10371111111.11111,32.68046061060966,1.353542365330074e-09,0.67,1100.0
0.0005,20.0,207422222.2222222,10371111111.11111,51.561759972218745,5.062063947965083e-09,0.67,1100.0
0.0005,20.0,207422222.2222222,10371111111.11111,51.30025765050833,5.036391017565642e-09,0.67,1100.0
0.0005,20.0,207422222.2222222,10371111111.11111,51.28827963465231,5.035215078608835e-09,0.67,1100.0
0.0005,20.0,207422222.2222222,10371111111.11111,51.017433044737714,5.008624776823661e-09,0.67,1100.0
0.0005,20.0,207422222.2222222,10371111111.11111,50.737520266011785,4.9811444040333085e-09,0.67,1100.0
0.0005,20.0,207422222.2222222,10371111111.11111,50.725549192517036,4.979969146641225e-09,0.67,1100.0
0.0005,20.0,207422222.2222222,10371111111.11111,50.43681785348517,4.95162301371736e-09,0.67,1100.0
0.0005,20.0,207422222.2222222,10371111111.11111,50.13954067729903,4.9224378951927885e-09,0.67,1100.0
0.0005,20.0,207422222.2222222,10371111111.11111,49.83397383424226,4.892438940526296e-09,0.67,1100.0
0.0005,20.0,207422222.2222222,10371111111.11111,49.82199581838625,4.891263001569488e-09,0.67,1100.0
0.000625,25.0,324097222.2222222,10371111111.11111,71.1705077503466,1.3646773944137228e-08,0.67,1100.0
0.000625,25.0,324097222.2222222,10371111111.11111,70.87957825075549,1.3590988911261983e-08,0.67,1100.0
0.000625,25.0,324097222.2222222,10371111111.11111,70.86999676371885,1.3589151684132787e-08,0.67,1100.0
0.000625,25.0,324097222.2222222,10371111111.11111,70.57064641234146,1.3531751973150322e-08,0.67,1100.0
0.000625,25.0,324097222.2222222,10371111111.11111,70.26307365448218,1.3472775635471181e-08,0.67,1100.0
0.000625,25.0,324097222.2222222,10371111111.11111,69.94746651480678,1.3412258724373478e-08,0.67,1100.0
0.000625,25.0,324097222.2222222,10371111111.11111,69.93788058465893,1.3410420645288377e-08,0.67,1100.0
0.000625,25.0,324097222.2222222,10371111111.11111,69.61441667022912,1.3348397216499675e-08,0.67,1100.0
0.000625,25.0,324097222.2222222,10371111111.11111,69.28328983220777,1.3284904440514916e-08,0.67,1100.0
0.000625,25.0,324097222.2222222,10371111111.11111,69.27370834517114,1.328306721338572e-08,0.67,1100.0
0.00075,30.0,466699999.99999994,10371111111.11111,92.82422483368174,3.075636474977292e-08,0.67,1100.0
0.00075,30.0,466699999.99999994,10371111111.11111,92.50677238522347,3.0651180103060436e-08,0.67,1100.0
0.00075,30.0,466699999.99999994,10371111111.11111,92.18160235197564,3.0543438312960004e-08,0.67,1100.0
0.00075,30.0,466699999.99999994,10371111111.11111,92.17361212270632,3.0540790831590975e-08,0.67,1100.0
0.00075,30.0,466699999.99999994,10371111111.11111,91.84086276150994,3.043053770810358e-08,0.67,1100.0
0.00075,30.0,466699999.99999994,10371111111.11111,91.5006836989261,3.0317822828471554e-08,0.67,1100.0
0.00075,30.0,466699999.99999994,10371111111.11111,91.49269655515066,3.0315176369449607e-08,0.67,1100.0
0.00075,30.0,466699999.99999994,10371111111.11111,91.14522410510911,3.020004489991002e-08,0.67,1100.0
0.00075,30.0,466699999.99999994,10371111111.11111,90.79060595446114,3.008254577500204e-08,0.67,1100.0
0.00025,10.0,87061111.1111111,17412222222.22222,32.99058973873083,4.048554467218422e-10,0.67,1100.0
0.00025,10.0,87061111.1111111,17412222222.22222,32.966642115732945,4.0456156517308784e-10,0.67,1100.0
0.00025,10.0,87061111.1111111,17412222222.22222,32.78544015193023,4.023378825234838e-10,0.67,1100.0
0.00025,10.0,87061111.1111111,17412222222.22222,32.59641809552559,4.0001823289939296e-10,0.67,1100.0
0.00025,10.0,87061111.1111111,17412222222.22222,32.57248701263363,3.9972455432827637e-10,0.67,1100.0
0.00025,10.0,87061111.1111111,17412222222.22222,32.375877138027036,3.9731178816543547e-10,0.67,1100.0
0.00025,10.0,87061111.1111111,17412222222.22222,32.171974662278124,3.9480952832222623e-10,0.67,1100.0
0.00025,10.0,87061111.1111111,17412222222.22222,31.961038513988104,3.9222095233064637e-10,0.67,1100.0
0.00025,10.0,87061111.1111111,17412222222.22222,31.937090890990213,3.91927070781892e-10,0.67,1100.0
0.00025,10.0,87061111.1111111,17412222222.22222,31.719343719836118,3.892549109645574e-10,0.67,1100.0
0.000375,15.0,195887499.99999997,17412222222.22222,57.604762475418596,2.3858441710562115e-09,0.67,1100.0
0.000375,15.0,195887499.99999997,17412222222.22222,57.58879310524439,2.385182759966081e-09,0.67,1100.0
0.000375,15.0,195887499.99999997,17412222222.22222,57.36603682306331,2.375956755820423e-09,0.67,1100.0
0.000375,15.0,195887499.99999997,17412222222.22222,57.13678884629764,2.3664618820358774e-09,0.67,1100.0
0.000375,15.0,195887499.99999997,17412222222.22222,56.90119444332675,2.356704155262828e-09,0.67,1100.0
0.000375,15.0,195887499.99999997,17412222222.22222,56.885217721994366,2.356042439706241e-09,0.67,1100.0
0.000375,15.0,195887499.99999997,17412222222.22222,56.64340629166703,2.3460272193190823e-09,0.67,1100.0
0.000375,15.0,195887499.99999997,17412222222.22222,56.395535472541795,2.3357610343098617e-09,0.67,1100.0
0.000375,15.0,195887499.99999997,17412222222.22222,56.37956610236759,2.3350996232197314e-09,0.67,1100.0
0.000375,15.0,195887499.99999997,17412222222.22222,56.1257629657414,2.32458773656151e-09,0.67,1100.0
0.0005,20.0,348244444.4444444,17412222222.22222,86.6899816729756,8.510769048864186e-09,0.67,1100.0
0.0005,20.0,348244444.4444444,17412222222.22222,86.43297095361278,8.485537080494059e-09,0.67,1100.0
0.0005,20.0,348244444.4444444,17412222222.22222,86.4209840478633,8.484360268774002e-09,0.67,1100.0
0.0005,20.0,348244444.4444444,17412222222.22222,86.15830080060968,8.458571401280468e-09,0.67,1100.0
0.0005,20.0,348244444.4444444,17412222222.22222,85.89004785805794,8.432235730229706e-09,0.67,1100.0
0.0005,20.0,348244444.4444444,17412222222.22222,85.87806508733495,8.431059324464924e-09,0.67,1100.0
0.0005,20.0,348244444.4444444,17412222222.22222,85.60432817385353,8.404185265827126e-09,0.67,1100.0
0.0005,20.0,348244444.4444444,17412222222.22222,85.32520898663276,8.376782803700602e-09,0.67,1100.0
0.0005,20.0,348244444.4444444,17412222222.22222,85.04080038636162,8.348861054662179e-09,0.67,1100.0
0.0005,20.0,348244444.4444444,17412222222.22222,85.02881348061214,8.347684242942122e-09,0.67,1100.0
0.000625,25.0,544131944.4444444,17412222222.22222,119.62501672664376,2.2937809676146256e-08,0.67,1100.0
0.000625,25.0,544131944.4444444,17412222222.22222,119.33812045729466,2.2882798005484058e-08,0.67,1100.0
0.000625,25.0,544131944.4444444,17412222222.22222,119.32853148403194,2.2880959342888987e-08,0.67,1100.0
0.000625,25.0,544131944.4444444,17412222222.22222,119.0365430046705,2.2824971253185938e-08,0.67,1100.0
0.000625,25.0,544131944.4444444,17412222222.22222,118.73953533501381,2.276802074579743e-08,0.67,1100.0
0.000625,25.0,544131944.4444444,17412222222.22222,118.43757587702183,2.2710120744887422e-08,0.67,1100.0
0.000625,25.0,544131944.4444444,17412222222.22222,118.42798425734215,2.2708281574848258e-08,0.67,1100.0
0.000625,25.0,544131944.4444444,17412222222.22222,118.12113479559939,2.264944392746245e-08,0.67,1100.0
0.000625,25.0,544131944.4444444,17412222222.22222,117.80946737619787,2.2589682448265973e-08,0.67,1100.0
0.000625,25.0,544131944.4444444,17412222222.22222,117.79987840293515,2.2587843785670902e-08,0.67,1100.0
0.00075,30.0,783549999.9999999,17412222222.22222,155.99199786914096,5.168636520375458e-08,0.67,1100.0
0.00075,30.0,783549999.9999999,17412222222.22222,155.67823586757513,5.158240334916254e-08,0.67,1100.0
0.00075,30.0,783549999.9999999,17412222222.22222,155.35981882577593,5.147689909423699e-08,0.67,1100.0
0.00075,30.0,783549999.9999999,17412222222.22222,155.3518246454428,5.147425030372308e-08,0.67,1100.0
0.00075,30.0,783549999.9999999,17412222222.22222,155.02880042856114,5.136721950809593e-08,0.67,1100.0
0.00075,30.0,783549999.9999999,17412222222.22222,154.70122404709738,5.125868039893814e-08,0.67,1100.0
0.00075,30.0,783549999.9999999,17412222222.22222,154.69323170455382,5.125603221735715e-08,0.67,1100.0
0.00075,30.0,783549999.9999999,17412222222.22222,154.36115061224325,5.1146000517982253e-08,0.67,1100.0
0.00075,30.0,783549999.9999999,17412222222.22222,154.0246194085733,5.1034494319376245e-08,0.67,1100.0
0.00025,10.0,122266666.66666666,24453333333.333332,46.38267486912755,5.692010571199024e-10,0.67,1100.0
0.00025,10.0,122266666.66666666,24453333333.333332,46.35871216465644,5.689069904936267e-10,0.67,1100.0
0.00025,10.0,122266666.66666666,24453333333.333332,46.180205114067356,5.667163794047805e-10,0.67,1100.0
0.00025,10.0,122266666.66666666,24453333333.333332,45.99603829664093,5.644563125271951e-10,0.67,1100.0
0.00025,10.0,122266666.66666666,24453333333.333332,45.97208736970527,5.641623904330242e-10,0.67,1100.0
0.00025,10.0,122266666.66666666,24453333333.333332,45.7823727926781,5.61834242302292e-10,0.67,1100.0
0.00025,10.0,122266666.66666666,24453333333.333332,45.58726840907068,5.594399512936035e-10,0.67,1100.0
0.00025,10.0,122266666.66666666,24453333333.333332,45.38690745491761,5.569811524590976e-10,0.67,1100.0
0.00025,10.0,122266666.66666666,24453333333.333332,45.3629447504465,5.566870858328219e-10,0.67,1100.0
0.00025,10.0,122266666.66666666,24453333333.333332,45.15743574724235,5.541651109316004e-10,0.67,1100.0
0.000375,15.0,275100000.0,24453333333.333332,80.96169980086603,3.3532296853255172e-09,0.67,1100.0
0.000375,15.0,275100000.0,24453333333.333332,80.94572161111685,3.3525679089508055e-09,0.67,1100.0
0.000375,15.0,275100000.0,24453333333.333332,80.72518264809386,3.3434337405798536e-09,0.67,1100.0
0.000375,15.0,275100000.0,24453333333.333332,80.49997131167676,3.3341060542713507e-09,0.67,1100.0
0.000375,15.0,275100000.0,24453333333.333332,80.27016162678649,3.3245879159510736e-09,0.67,1100.0
0.000375,15.0,275100000.0,24453333333.333332,80.25417820257711,3.3239259227782045e-09,0.67,1100.0
0.000375,15.0,275100000.0,24453333333.333332,80.01983330317539,3.3142199472958313e-09,0.67,1100.0
0.000375,15.0,275100000.0,24453333333.333332,79.78103683961422,3.3043295992382487e-09,0.67,1100.0
0.000375,15.0,275100000.0,24453333333.333332,79.76505864986503,3.303667822863537e-09,0.67,1100.0
0.000375,15.0,275100000.0,24453333333.333332,79.52187291379398,3.293595682193975e-09,0.67,1100.0
0.0005,20.0,489066666.6666666,24453333333.333332,121.81770456472675,1.1959425179303668e-08,0.67,1100.0
0.0005,20.0,489066666.6666666,24453333333.333332,121.56261790979272,1.193438210551712e-08,0.67,1100.0
0.0005,20.0,489066666.6666666,24453333333.333332,121.55062723367494,1.193320492364202e-08,0.67,1100.0
0.0005,20.0,489066666.6666666,24453333333.333332,121.2914689618742,1.1907762119804325e-08,0.67,1100.0
0.0005,20.0,489066666.6666666,24453333333.333332,121.02829308776128,1.1881924888781974e-08,0.67,1100.0
0.0005,20.0,489066666.6666666,24453333333.333332,121.01630535602737,1.1880747995971086e-08,0.67,1100.0
0.0005,20.0,489066666.6666666,24453333333.333332,120.74915391127985,1.1854520464214375e-08,0.67,1100.0
0.0005,20.0,489066666.6666666,24453333333.333332,120.47808049998386,1.1827907894292157e-08,0.67,1100.0
0.0005,20.0,489066666.6666666,24453333333.333332,120.20313263254512,1.1800914950527603e-08,0.67,1100.0
0.0005,20.0,489066666.6666666,24453333333.333332,120.19114195642734,1.1799737768652504e-08,0.67,1100.0
0.000625,25.0,764166666.6666666,24453333333.333332,168.07907954602834,3.2228759858638744e-08,0.67,1100.0
0.000625,25.0,764166666.6666666,24453333333.333332,167.79390750723886,3.217407880504559e-08,0.67,1100.0
0.000625,25.0,764166666.6666666,24453333333.333332,167.78431535892915,3.2172239533642885e-08,0.67,1100.0
0.000625,25.0,764166666.6666666,24453333333.333332,167.4954941486713,3.211685876018421e-08,0.67,1100.0
0.000625,25.0,764166666.6666666,24453333333.333332,167.203061978074,3.2060785593752215e-08,0.67,1100.0
0.000625,25.0,764166666.6666666,24453333333.333332,166.90705317204052,3.200402661606467e-08,0.67,1100.0
0.000625,25.0,764166666.6666666,24453333333.333332,166.89745913932512,3.20021869833317e-08,0.67,1100.0
0.000625,25.0,764166666.6666666,24453333333.333332,166.59790413663174,3.194474803095087e-08,0.67,1100.0
0.000625,25.0,764166666.6666666,24453333333.333332,166.29484079645903,3.188663636328369e-08,0.67,1100.0
0.000625,25.0,764166666.6666666,24453333333.333332,166.28524864814932,3.188479709188099e-08,0.67,1100.0
0.00075,30.0,1100400000.0,24453333333.333332,219.15936379293478,7.261623076541802e-08,0.67,1100.0
0.00075,30.0,1100400000.0,24453333333.333332,218.8471773700183,7.251279096281961e-08,0.67,1100.0
0.00075,30.0,1100400000.0,24453333333.333332,218.53165862418524,7.240824702884526e-08,0.67,1100.0
0.00075,30.0,1100400000.0,24453333333.333332,218.52366276813288,7.240559768309879e-08,0.67,1100.0
0.00075,30.0,1100400000.0,24453333333.333332,218.2048352799122,7.229995743091743e-08,0.67,1100.0
0.00075,30.0,1100400000.0,24453333333.333332,217.8827277899339,7.219323038344511e-08,0.67,1100.0
0.00075,30.0,1100400000.0,24453333333.333332,217.87473324249663,7.219058147129496e-08,0.67,1100.0
0.00075,30.0,1100400000.0,24453333333.333332,217.54936918262257,7.208277539244126e-08,0.67,1100.0
0.00075,30.0,1100400000.0,24453333333.333332,217.22077714491834,7.197389975589691e-08,0.67,1100.0
0.00025,10.0,157472222.2222222,31494444444.444443,59.77452703680778,7.335438086353117e-10,0.67,1100.0
0.00025,10.0,157472222.2222222,31494444444.444443,59.75055599429587,7.332496396858808e-10,0.67,1100.0
0.00025,10.0,157472222.2222222,31494444444.444443,59.5735527087055,7.310774825699746e-10,0.67,1100.0
0.00025,10.0,157472222.2222222,31494444444.444443,59.3921155712551,7.288509139055116e-10,0.67,1100.0
0.00025,10.0,157472222.2222222,31494444444.444443,59.368153673213115,7.285568571756102e-10,0.67,1100.0
0.00025,10.0,157472222.2222222,31494444444.444443,59.182346458973235,7.26276659600454e-10,0.67,1100.0
0.00025,10.0,157472222.2222222,31494444444.444443,58.99226897521016,7.239440579340364e-10,0.67,1100.0
0.00025,10.0,157472222.2222222,31494444444.444443,58.79800219545327,7.215600458710645e-10,0.67,1100.0
0.00025,10.0,157472222.2222222,31494444444.444443,58.77403115294136,7.212658769216337e-10,0.67,1100.0
0.00025,10.0,157472222.2222222,31494444444.444443,58.57563721787107,7.188312170429868e-10,0.67,1100.0
0.000375,15.0,354312499.99999994,31494444444.444443,104.31844661477825,4.320607309086881e-09,0.67,1100.0
0.000375,15.0,354312499.99999994,31494444444.444443,104.3024635489818,4.319945330758573e-09,0.67,1100.0
0.000375,15.0,354312499.99999994,31494444444.444443,104.08315800653692,4.310862247561316e-09,0.67,1100.0
0.000375,15.0,354312499.99999994,31494444444.444443,103.86020318910062,4.3016280205854425e-09,0.67,1100.0
0.000375,15.0,354312499.99999994,31494444444.444443,103.63364384584273,4.2922445032288555e-09,0.67,1100.0
0.000375,15.0,354312499.99999994,31494444444.444443,103.61765671583744,4.291582356571254e-09,0.67,1100.0
0.000375,15.0,354312499.99999994,31494444444.444443,103.38752926980136,4.282051057384671e-09,0.67,1100.0
0.000375,15.0,354312499.99999994,31494444444.444443,103.15388620337109,4.272374150056249e-09,0.67,1100.0
0.000375,15.0,354312499.99999994,31494444444.444443,103.13790313757465,4.271712171727942e-09,0.67,1100.0
0.000375,15.0,354312499.99999994,31494444444.444443,102.90078047901785,4.2618911484577826e-09,0.67,1100.0
0.0005,20.0,629888888.8888888,31494444444.444443,156.9452625156672,1.5408065116716924e-08,0.67,1100.0
0.0005,20.0,629888888.8888888,31494444444.444443,156.69124450735305,1.5383126957066948e-08,0.67,1100.0
0.0005,20.0,629888888.8888888,31494444444.444443,156.67925174672504,1.5381949570545537e-08,0.67,1100.0
0.0005,20.0,629888888.8888888,31494444444.444443,156.4220584410768,1.5356699676808756e-08,0.67,1100.0
0.0005,20.0,629888888.8888888,31494444444.444443,156.16172348289405,1.5331141352055644e-08,0.67,1100.0
0.0005,20.0,629888888.8888888,31494444444.444443,156.14973300838352,1.532996418997329e-08,0.67,1100.0
0.0005,20.0,629888888.8888888,31494444444.444443,155.88628080182173,1.5304099830076212e-08,0.67,1100.0
0.0005,20.0,629888888.8888888,31494444444.444443,155.6197447994098,1.5277932719229507e-08,0.67,1100.0
0.0005,20.0,629888888.8888888,31494444444.444443,155.35015378542326,1.525146568332282e-08,0.67,1100.0
0.0005,20.0,629888888.8888888,31494444444.444443,155.33816102479526,1.525028829680141e-08,0.67,1100.0
0.000625,25.0,984201388.8888888,31494444444.444443,216.53299495767985,4.151968177605242e-08,0.67,1100.0
0.000625,25.0,984201388.8888888,31494444444.444443,216.24877968966194,4.1465184180957015e-08,0.67,1100.0
0.000625,25.0,984201388.8888888,31494444444.444443,216.23918578597522,4.1463344572964984e-08,0.67,1100.0
0.000625,25.0,984201388.8888888,31494444444.444443,215.95212719521686,4.140830177756238e-08,0.67,1100.0
0.000625,25.0,984201388.8888888,31494444444.444443,215.66224900575529,4.135271833087974e-08,0.67,1100.0
0.000625,25.0,984201388.8888888,31494444444.444443,215.3695719604118,4.129659821030323e-08,0.67,1100.0
0.000625,25.0,984201388.8888888,31494444444.444443,215.35997659360987,4.1294758321762375e-08,0.67,1100.0
0.000625,25.0,984201388.8888888,31494444444.444443,215.06451845402557,4.123810493304403e-08,0.67,1100.0
0.000625,25.0,984201388.8888888,31494444444.444443,214.76630277938793,4.1180922793601465e-08,0.67,1100.0
0.000625,25.0,984201388.8888888,31494444444.444443,214.7567088757012,4.1179083185609434e-08,0.67,1100.0
0.00075,30.0,1417249999.9999998,31494444444.444443,282.32659528375535,9.354605178408024e-08,0.67,1100.0
0.00075,30.0,1417249999.9999998,31494444444.444443,282.01528260759216,9.344290148860017e-08,0.67,1100.0
0.00075,30.0,1417249999.9999998,31494444444.444443,281.70137501309665,9.333889139326864e-08,0.67,1100.0
0.00075,30.0,1417249999.9999998,31494444444.444443,281.69337823059533,9.33362417405527e-08,0.67,1100.0
0.00075,30.0,1417249999.9999998,31494444444.444443,281.3768895006686,9.323137641219408e-08,0.67,1100.0
0.00075,30.0,1417249999.9999998,31494444444.444443,281.0578374476008,9.31256617527299e-08,0.67,1100.0
0.00075,30.0,1417249999.9999998,31494444444.444443,281.04984168115163,9.312301243667255e-08,0.67,1100.0
0.00075,30.0,1417249999.9999998,31494444444.444443,280.7282400182222,9.301645298985881e-08,0.67,1100.0
0.00075,30.0,1417249999.9999998,31494444444.444443,280.4041064881376,9.290905463456119e-08,0.67,1100.0
0.00025,10.0,192677777.7777778,38535555555.55556,73.16627351411728,8.978852631347355e-10,0.67,1100.0
0.00025,10.0,192677777.7777778,38535555555.55556,73.1422971805725,8.975910292545624e-10,0.67,1100.0
0.00025,10.0,192677777.7777778,38535555555.55556,72.96625325708999,8.954306452829931e-10,0.67,1100.0
0.00025,10.0,192677777.7777778,38535555555.55556,72.78656512208734,8.932255401077526e-10,0.67,1100.0
0.00025,10.0,192677777.7777778,38535555555.55556,72.76259626216,8.929313979426642e-10,0.67,1100.0
0.00025,10.0,192677777.7777778,38535555555.55556,72.57930392758261,8.906820625841968e-10,0.67,1100.0
0.00025,10.0,192677777.7777778,38535555555.55556,72.3924770017183,8.88389351264712e-10,0.67,1100.0
0.00025,10.0,192677777.7777778,38535555555.55556,72.20216984788813,8.860539311225305e-10,0.67,1100.0
0.00025,10.0,192677777.7777778,38535555555.55556,72.17819351434335,8.857596972423574e-10,0.67,1100.0
0.00025,10.0,192677777.7777778,38535555555.55556,71.98444525129759,8.833820483367702e-10,0.67,1100.0
0.000375,15.0,433525000.0,38535555555.55556,127.67510711447422,5.287981357930809e-09,0.67,1100.0
0.000375,15.0,433525000.0,38535555555.55556,127.6591209545065,5.2873192514497205e-09,0.67,1100.0
0.000375,15.0,433525000.0,38535555555.55556,127.44060088759316,5.278268700670582e-09,0.67,1100.0
0.000375,15.0,433525000.0,38535555555.55556,127.21908716612303,5.269094160259899e-09,0.67,1100.0
0.000375,15.0,433525000.0,38535555555.55556,126.99460973266658,5.259796870363525e-09,0.67,1100.0
0.000375,15.0,433525000.0,38535555555.55556,126.97862025109112,5.25913462630981e-09,0.67,1100.0
0.000375,15.0,433525000.0,38535555555.55556,126.75120229701625,5.24971554745579e-09,0.67,1100.0
0.000375,15.0,433525000.0,38535555555.55556,126.5208801922304,5.2401761859940844e-09,0.67,1100.0
0.000375,15.0,433525000.0,38535555555.55556,126.50489403226268,5.239514079512996e-09,0.67,1100.0
0.000375,15.0,433525000.0,38535555555.55556,126.27169075244606,5.22985538703841e-09,0.67,1100.0
0.0005,20.0,770711111.1111112,38535555555.55556,192.07274578794815,1.885669772256993e-08,0.67,1100.0
0.0005,20.0,770711111.1111112,38535555555.55556,191.81940771646327,1.8831826315562072e-08,0.67,1100.0
0.0005,20.0,770711111.1111112,38535555555.55556,191.8074136330771,1.8830648799179178e-08,0.67,1100.0
0.0005,20.0,770711111.1111112,38535555555.55556,191.55147319668288,1.8805521905593784e-08,0.67,1100.0
0.0005,20.0,770711111.1111112,38535555555.55556,191.292953576683,1.878014180125002e-08,0.67,1100.0
0.0005,20.0,770711111.1111112,38535555555.55556,191.28096136170117,1.8778964468297296e-08,0.67,1100.0
0.0005,20.0,770711111.1111112,38535555555.55556,191.01987821325878,1.8753332690137212e-08,0.67,1100.0
0.0005,20.0,770711111.1111112,38535555555.55556,190.7562546126669,1.8727451503670577e-08,0.67,1100.0
0.0005,20.0,770711111.1111112,38535555555.55556,190.49010984695633,1.870132280239721e-08,0.67,1100.0
0.0005,20.0,770711111.1111112,38535555555.55556,190.47811576357012,1.8700145286014315e-08,0.67,1100.0
0.000625,25.0,1204236111.1111112,38535555555.55556,264.986843655879,5.081059090132182e-08,0.67,1100.0
0.000625,25.0,1204236111.1111112,38535555555.55556,264.70323681610154,5.075620997088037e-08,0.67,1100.0
0.000625,25.0,1204236111.1111112,38535555555.55556,264.69364179851317,5.0754370149300374e-08,0.67,1100.0
0.000625,25.0,1204236111.1111112,38535555555.55556,264.4077059761634,5.069954264204378e-08,0.67,1100.0
0.000625,25.0,1204236111.1111112,38535555555.55556,264.11945746926204,5.064427168307834e-08,0.67,1100.0
0.000625,25.0,1204236111.1111112,38535555555.55556,263.8289101542457,5.0588559933177494e-08,0.67,1100.0
0.000625,25.0,1204236111.1111112,38535555555.55556,263.81931394087854,5.0586719882309786e-08,0.67,1100.0
0.000625,25.0,1204236111.1111112,38535555555.55556,263.52647927261614,5.053056953791711e-08,0.67,1100.0
0.000625,25.0,1204236111.1111112,38535555555.55556,263.23137345909686,5.047398370687562e-08,0.67,1100.0
0.000625,25.0,1204236111.1111112,38535555555.55556,263.2217784415085,5.047214388529562e-08,0.67,1100.0
0.00075,30.0,1734100000.0,38535555555.55556,345.49376594955663,1.1447585264898969e-07,0.67,1100.0
0.00075,30.0,1734100000.0,38535555555.55556,345.1830087069527,1.1437288639078193e-07,0.67,1100.0
0.00075,30.0,1734100000.0,38535555555.55556,344.8701267413811,1.1426921612718438e-07,0.67,1100.0
0.00075,30.0,1734100000.0,38535555555.55556,344.86212937098725,1.1426656627967622e-07,0.67,1100.0
0.00075,30.0,1734100000.0,38535555555.55556,344.5471315945046,1.1416219496360839e-07,0.67,1100.0
0.00075,30.0,1734100000.0,38535555555.55556,344.23003022176187,1.1405712664227089e-07,0.67,1100.0
0.00075,30.0,1734100000.0,38535555555.55556,344.2220336817699,1.1405447706990798e-07,0.67,1100.0
0.00075,30.0,1734100000.0,38535555555.55556,343.90283758680545,1.1394871468362336e-07,0.67,1100.0
0.00075,30.0,1734100000.0,38535555555.55556,343.5815589462681,1.138422622670006e-07,0.67,1100.0
0.00025,10.0,227883333.3333333,45576666666.666664,86.55796314721191,1.0622260200506913e-09,0.67,1100.0
0.00025,10.0,227883333.3333333,45576666666.666664,86.53398315745105,1.0619317413019965e-09,0.67,1100.0
0.00025,10.0,227883333.3333333,45576666666.666664,86.35860450235438,1.0597795214018085e-09,0.67,1100.0
0.00025,10.0,227883333.3333333,45576666666.666664,86.18013262804283,1.0575893419908335e-09,0.67,1100.0
0.00025,10.0,227883333.3333333,45576666666.666664,86.15615895730487,1.0572951407882166e-09,0.67,1100.0
0.00025,10.0,227883333.3333333,45576666666.666664,85.97462058679501,1.055067329807207e-09,0.67,1100.0
0.00025,10.0,227883333.3333333,45576666666.666664,85.79006753889476,1.0528025231686092e-09,0.67,1100.0
0.00025,10.0,227883333.3333333,45576666666.666664,85.60253881426802,1.0505011994825762e-09,0.67,1100.0
0.00025,10.0,227883333.3333333,45576666666.666664,85.57855882450716,1.0502069207338814e-09,0.67,1100.0
0.00025,10.0,227883333.3333333,45576666666.666664,85.38808060587621,1.047869401310757e-09,0.67,1100.0
0.000375,15.0,512737499.99999994,45576666666.666664,151.03172122886812,6.2553534856123585e-09,0.67,1100.0
0.000375,15.0,512737499.99999994,45576666666.666664,151.01573293076237,6.254691290574977e-09,0.67,1100.0
0.000375,15.0,512737499.99999994,45576666666.666664,150.79775691096182,6.2456632728569445e-09,0.67,1100.0
0.000375,15.0,512737499.99999994,45576666666.666664,150.57724319321255,6.236530150081644e-09,0.67,1100.0
0.000375,15.0,512737499.99999994,45576666666.666664,150.35421320895819,6.22729280988549e-09,0.67,1100.0
0.000375,15.0,512737499.99999994,45576666666.666664,150.3382221023978,6.226630498528992e-09,0.67,1100.0
0.000375,15.0,512737499.99999994,45576666666.666664,150.11269160087653,6.217289593205765e-09,0.67,1100.0
0.000375,15.0,512737499.99999994,45576666666.666664,149.8846874998982,6.207846237623348e-09,0.67,1100.0
0.000375,15.0,512737499.99999994,45576666666.666664,149.86869920179245,6.207184042585967e-09,0.67,1100.0
0.000375,15.0,512737499.99999994,45576666666.666664,149.63823712014974,6.197638883635414e-09,0.67,1100.0
0.0005,20.0,911533333.3333333,45576666666.666664,227.20018894412212,2.2305326390033342e-08,0.67,1100.0
0.0005,20.0,911533333.3333333,45576666666.666664,226.94732154548095,2.228050119122386e-08,0.67,1100.0
0.0005,20.0,911533333.3333333,45576666666.666664,226.93532654804076,2.2279323585103924e-08,0.67,1100.0
0.0005,20.0,911533333.3333333,45576666666.666664,226.68025458295787,2.225428195349014e-08,0.67,1100.0
0.0005,20.0,911533333.3333333,45576666666.666664,226.4229951241577,2.2229025565182855e-08,0.67,1100.0
0.0005,20.0,911533333.3333333,45576666666.666664,226.4110017064732,2.2227848114155074e-08,0.67,1100.0
0.0005,20.0,911533333.3333333,45576666666.666664,226.15156547590112,2.2202378021778816e-08,0.67,1100.0
0.0005,20.0,911533333.3333333,45576666666.666664,225.88996948278782,2.21766958952109e-08,0.67,1100.0
0.0005,20.0,911533333.3333333,45576666666.666664,225.62622754513222,2.2150803091030202e-08,0.67,1100.0
0.0005,20.0,911533333.3333333,45576666666.666664,225.614232547692,2.2149625484910265e-08,0.67,1100.0
0.000625,25.0,1424270833.3333333,45576666666.666664,313.44065652543435,6.010149315653482e-08,0.67,1100.0
0.000625,25.0,1424270833.3333333,45576666666.666664,313.15747071014954,6.004719295652874e-08,0.67,1100.0
0.000625,25.0,1424270833.3333333,45576666666.666664,313.14787492283153,6.004535298735493e-08,0.67,1100.0
0.000625,25.0,1424270833.3333333,45576666666.666664,312.862716897054,5.999067462072315e-08,0.67,1100.0
0.000625,25.0,1424270833.3333333,45576666666.666664,312.57559863162476,5.993562038284572e-08,0.67,1100.0
0.000625,25.0,1424270833.3333333,45576666666.666664,312.286530057144,5.988019217789134e-08,0.67,1100.0
0.000625,25.0,1424270833.3333333,45576666666.666664,312.27693325878215,5.987835201485232e-08,0.67,1100.0
0.000625,25.0,1424270833.3333333,45576666666.666664,311.985922265618,5.982255135578015e-08,0.67,1100.0
0.000625,25.0,1424270833.3333333,45576666666.666664,311.6929807701759,5.976638052753231e-08,0.67,1100.0
0.000625,25.0,1424270833.3333333,45576666666.666664,311.6833849828578,5.976454055835849e-08,0.67,1100.0
0.00075,30.0,2050949999.9999998,45576666666.666664,408.66090395438994,1.354056426920189e-07,0.67,1100.0
0.00075,30.0,2050949999.9999998,45576666666.666664,408.35053097482273,1.3530280375546816e-07,0.67,1100.0
0.00075,30.0,2050949999.9999998,45576666666.666664,408.0383592154527,1.3519936881148703e-07,0.67,1100.0
0.00075,30.0,2050949999.9999998,45576666666.666664,408.0303614388126,1.351967188293733e-07,0.67,1100.0
0.00075,30.0,2050949999.9999998,45576666666.666664,407.7163970583766,1.3509268991859674e-07,0.67,1100.0
0.00075,30.0,2050949999.9999998,45576666666.666664,407.40064901257114,1.349880700084039e-07,0.67,1100.0
0.00075,30.0,2050949999.9999998,45576666666.666664,407.3926519380447,1.349854202589284e-07,0.67,1100.0
0.00075,30.0,2050949999.9999998,45576666666.666664,407.0751263626217,1.3488021138233836e-07,0.67,1100.0
0.00075,30.0,2050949999.9999998,45576666666.666664,406.7558321903017,1.3477441649911746e-07,0.67,1100.0
0.00025,10.0,263088888.88888887,52617777777.77777,99.94961870054307,1.2265663587450278e-09,0.67,1100.0
0.00025,10.0,263088888.88888887,52617777777.77777,99.92563603308804,1.2262720471360817e-09,0.67,1100.0
0.00025,10.0,263088888.88888887,52617777777.77777,99.7507458077714,1.2241258211710838e-09,0.67,1100.0
0.00025,10.0,263088888.88888887,52617777777.77777,99.57316866415698,1.2219466217577068e-09,0.67,1100.0
0.00025,10.0,263088888.88888887,52617777777.77777,99.5491914701372,1.221652377317917e-09,0.67,1100.0
0.00025,10.0,263088888.88888887,52617777777.77777,99.36894603219524,1.2194404330066608e-09,0.67,1100.0
0.00025,10.0,263088888.88888887,52617777777.77777,99.18607270041765,1.2171962395861534e-09,0.67,1100.0
0.00025,10.0,263088888.88888887,52617777777.77777,99.00060081132003,1.2149201570696044e-09,0.67,1100.0
0.00025,10.0,263088888.88888887,52617777777.77777,98.976618143865,1.2146258454606583e-09,0.67,1100.0
0.00025,10.0,263088888.88888887,52617777777.77777,98.7885659701002,1.2123180980872555e-09,0.67,1100.0
0.000375,15.0,591949999.9999999,52617777777.77777,174.38830754907815,7.222724462128817e-09,0.67,1100.0
0.000375,15.0,591949999.9999999,52617777777.77777,174.3723176850694,7.222062202235677e-09,0.67,1100.0
0.000375,15.0,591949999.9999999,52617777777.77777,174.15474076505126,7.213050714225409e-09,0.67,1100.0
0.000375,15.0,591949999.9999999,52617777777.77777,173.9349615854654,7.203948014170736e-09,0.67,1100.0
0.000375,15.0,591949999.9999999,52617777777.77777,173.71299623998434,7.194754768631038e-09,0.67,1100.0
0.000375,15.0,591949999.9999999,52617777777.77777,173.69700394333765,7.1940924079841634e-09,0.67,1100.0
0.000375,15.0,591949999.9999999,52617777777.77777,173.47286361791242,7.184809080253359e-09,0.67,1100.0
0.000375,15.0,591949999.9999999,52617777777.77777,173.2465691866278,7.175436534883464e-09,0.67,1100.0
0.000375,15.0,591949999.9999999,52617777777.77777,173.230579322619,7.174774274990324e-09,0.67,1100.0
0.000375,15.0,591949999.9999999,52617777777.77777,173.0021418866174,7.165312971762695e-09,0.67,1100.0
0.0005,20.0,1052355555.5555555,52617777777.77777,262.32760806916195,2.575395269824568e-08,0.67,1100.0
0.0005,20.0,1052355555.5555555,52617777777.77777,262.0750858025061,2.572916138268962e-08,0.67,1100.0
0.0005,20.0,1052355555.5555555,52617777777.77777,262.06309013564237,2.5727983710849182e-08,0.67,1100.0
0.0005,20.0,1052355555.5555555,52617777777.77777,261.80865561828244,2.570300466051926e-08,0.67,1100.0
0.0005,20.0,1052355555.5555555,52617777777.77777,261.5523220325732,2.567783916959012e-08,0.67,1100.0
0.0005,20.0,1052355555.5555555,52617777777.77777,261.5403277340683,2.5676661632087994e-08,0.67,1100.0
0.0005,20.0,1052355555.5555555,52617777777.77777,261.2821027682877,2.565131045535456e-08,0.67,1100.0
0.0005,20.0,1052355555.5555555,52617777777.77777,261.02199956351757,2.5625774882939532e-08,0.67,1100.0
0.0005,20.0,1052355555.5555555,52617777777.77777,260.7600285035005,2.5600055934264445e-08,0.67,1100.0
0.0005,20.0,1052355555.5555555,52617777777.77777,260.74803283663675,2.5598878262424006e-08,0.67,1100.0
0.000625,25.0,1644305555.5555553,52617777777.77777,361.8944479357115,6.939239129698275e-08,0.67,1100.0
0.000625,25.0,1644305555.5555553,52617777777.77777,361.6115707699385,6.933815027977933e-08,0.67,1100.0
0.000625,25.0,1644305555.5555553,52617777777.77777,361.6019744188953,6.933631020251257e-08,0.67,1100.0
0.000625,25.0,1644305555.5555553,52617777777.77777,361.31738703260316,6.928174125463173e-08,0.67,1100.0
0.000625,25.0,1644305555.5555553,52617777777.77777,361.0310986455355,6.922684614393717e-08,0.67,1100.0
0.000625,25.0,1644305555.5555553,52617777777.77777,360.74311671413824,6.917162630018447e-08,0.67,1100.0
0.000625,25.0,1644305555.5555553,52617777777.77777,360.73351948734546,6.916978605499483e-08,0.67,1100.0
0.000625,25.0,1644305555.5555553,52617777777.77777,360.4438497047699,6.911424256983208e-08,0.67,1100.0
0.000625,25.0,1644305555.5555553,52617777777.77777,360.1525012553761,6.905837720433828e-08,0.67,1100.0
0.000625,25.0,1644305555.5555553,52617777777.77777,360.14290490433285,6.905653712707152e-08,0.67,1100.0
0.00075,30.0,2367799999.9999995,52617777777.77777,471.828022399322,1.5633542625407334e-07,0.67,1100.0
0.00075,30.0,2367799999.9999995,52617777777.77777,471.51793107321095,1.5623268064053658e-07,0.67,1100.0
0.00075,30.0,2367799999.9999995,52617777777.77777,471.2062802109936,1.5612941829054e-07,0.67,1100.0
0.00075,30.0,2367799999.9999995,52617777777.77777,471.1982821368319,1.561267682098455e-07,0.67,1100.0
0.00075,30.0,2367799999.9999995,52617777777.77777,470.88507619898866,1.56022990601324e-07,0.67,1100.0
0.00075,30.0,2367799999.9999995,52617777777.77777,470.57032207116634,1.5591870001576678e-07,0.67,1100.0
0.00075,30.0,2367799999.9999995,52617777777.77777,470.5623246051642,1.5591605013657978e-07,0.67,1100.0
0.00075,30.0,2367799999.9999995,52617777777.77777,470.2460267329032,1.5581124804697151e-07,0.67,1100.0
0.00075,30.0,2367799999.9999995,52617777777.77777,469.9281919869158,1.5570593672985302e-07,0.67,1100.0
0.00025,10.0,298294444.4444444,59658888888.888885,113.34125221479017,1.3909064269791121e-09,0.67,1100.0
0.00025,10.0,298294444.4444444,59658888888.888885,113.31726750169909,1.3906120902664347e-09,0.67,1100.0
0.00025,10.0,298294444.4444444,59658888888.888885,113.14275110363333,1.3884704518520036e-09,0.67,1100.0
0.00025,10.0,298294444.4444444,59658888888.888885,112.96585976450183,1.386299668525835e-09,0.67,1100.0
0.00025,10.0,298294444.4444444,59658888888.888885,112.94187987885564,1.3860053910548195e-09,0.67,1100.0
0.00025,10.0,298294444.4444444,59658888888.888885,112.76262696977301,1.3838056269051765e-09,0.67,1100.0
0.00025,10.0,298294444.4444444,59658888888.888885,112.58104509118768,1.3815772819997517e-09,0.67,1100.0
0.00025,10.0,298294444.4444444,59658888888.888885,112.3971571082808,1.3793206369365342e-09,0.67,1100.0
0.00025,10.0,298294444.4444444,59658888888.888885,112.37317239518971,1.3790263002238568e-09,0.67,1100.0
0.00025,10.0,298294444.4444444,59658888888.888885,112.18699143794444,1.3767415161319815e-09,0.67,1100.0
0.000375,15.0,671162499.9999999,59658888888.888885,197.74487590208503,8.190094694488975e-09,0.67,1100.0
0.000375,15.0,671162499.9999999,59658888888.888885,197.7288848417978,8.189432385048995e-09,0.67,1100.0
0.000375,15.0,671162499.9999999,59658888888.888885,197.51161319045923,8.180433540498545e-09,0.67,1100.0
0.000375,15.0,671162499.9999999,59658888888.888885,197.29239640067595,8.171354133212989e-09,0.67,1100.0
0.000375,15.0,671162499.9999999,59658888888.888885,197.07124699990004,8.162194682047836e-09,0.67,1100.0
0.000375,15.0,671162499.9999999,59658888888.888885,197.05525379408175,8.161532283745364e-09,0.67,1100.0
0.000375,15.0,671162499.9999999,59658888888.888885,196.83217998957613,8.152293128624775e-09,0.67,1100.0
0.000375,15.0,671162499.9999999,59658888888.888885,196.60719854161775,8.142974963717206e-09,0.67,1100.0
0.000375,15.0,671162499.9999999,59658888888.888885,196.59120748133054,8.142312654277226e-09,0.67,1100.0
0.000375,15.0,671162499.9999999,59658888888.888885,196.36432653897873,8.132915817096189e-09,0.67,1100.0
0.0005,20.0,1193177777.7777777,59658888888.888885,297.4550116626154,2.9202577481648084e-08,0.67,1100.0
0.0005,20.0,1193177777.7777777,59658888888.888885,297.20275330408003,2.917781207521117e-08,0.67,1100.0
0.0005,20.0,1193177777.7777777,59658888888.888885,297.19075712580724,2.9176634353163267e-08,0.67,1100.0
0.0005,20.0,1193177777.7777777,59658888888.888885,296.9368103918042,2.915170319085242e-08,0.67,1100.0
0.0005,20.0,1193177777.7777777,59658888888.888885,296.6811858256538,2.9126607307755697e-08,0.67,1100.0
0.0005,20.0,1193177777.7777777,59658888888.888885,296.6691908542423,2.912542970419112e-08,0.67,1100.0
0.0005,20.0,1193177777.7777777,59658888888.888885,296.4118941576564,2.910016966007277e-08,0.67,1100.0
0.0005,20.0,1193177777.7777777,59658888888.888885,296.1529358456338,2.9074746487240393e-08,0.67,1100.0
0.0005,20.0,1193177777.7777777,59658888888.888885,295.8923240052999,2.9049160979645652e-08,0.67,1100.0
0.0005,20.0,1193177777.7777777,59658888888.888885,295.8803278270271,2.904798325759775e-08,0.67,1100.0
0.000625,25.0,1864340277.7777777,59658888888.888885,410.3482254782483,7.868328677832478e-08,0.67,1100.0
0.000625,25.0,1864340277.7777777,59658888888.888885,410.06558428031695,7.862909100738832e-08,0.67,1100.0
0.000625,25.0,1864340277.7777777,59658888888.888885,410.05598749861355,7.86272508475435e-08,0.67,1100.0
0.000625,25.0,1864340277.7777777,59658888888.888885,409.77183662854316,7.857276560059987e-08,0.67,1100.0
0.000625,25.0,1864340277.7777777,59658888888.888885,409.4861834428898,7.851799228825106e-08,0.67,1100.0
0.000625,25.0,1864340277.7777777,59658888888.888885,409.1990337453306,7.846293202333818e-08,0.67,1100.0
0.000625,25.0,1864340277.7777777,59658888888.888885,409.18943619123604,7.846109171538921e-08,0.67,1100.0
0.000625,25.0,1864340277.7777777,59658888888.888885,408.9007942325729,7.840574531299333e-08,0.67,1100.0
0.000625,25.0,1864340277.7777777,59658888888.888885,408.61066734508154,7.835011417906074e-08,0.67,1100.0
0.000625,25.0,1864340277.7777777,59658888888.888885,408.60107056337813,7.834827401921592e-08,0.67,1100.0
0.00075,30.0,2684649999.9999995,59658888888.888885,534.9951282049462,1.7726520562822146e-07,0.67,1100.0
0.00075,30.0,2684649999.9999995,59658888888.888885,534.6852521812248,1.771625313529462e-07,0.67,1100.0
0.00075,30.0,2684649999.9999995,59658888888.888885,534.3739996967511,1.7705940100137147e-07,0.67,1100.0
0.00075,30.0,2684649999.9999995,59658888888.888885,534.3660013952964,1.770567508453658e-07,0.67,1100.0
0.00075,30.0,2684649999.9999995,59658888888.888885,534.0533757946808,1.7695316552569438e-07,0.67,1100.0
0.00075,30.0,2684649999.9999995,59658888888.888885,533.7393825629387,1.7684912705533032e-07,0.67,1100.0
0.00075,30.0,2684649999.9999995,59658888888.888885,533.7313847978668,1.7684647707704961e-07,0.67,1100.0
0.00075,30.0,2684649999.9999995,59658888888.888885,533.4160272693576,1.7674198656079922e-07,0.67,1100.0
0.00075,30.0,2684649999.9999995,59658888888.888885,533.0993109188486,1.7663704581267096e-07,0.67,1100.0
0.00025,10.0,333500000.0,66700000000.0,126.73287065616266,1.5552463102411956e-09,0.67,1100.0
0.00025,10.0,333500000.0,66700000000.0,126.70888432932607,1.5549519537248815e-09,0.67,1100.0
0.00025,10.0,333500000.0,66700000000.0,126.53466325468654,1.5528139394741467e-09,0.67,1100.0
0.00025,10.0,333500000.0,66700000000.0,126.35831431720709,1.5506498124176866e-09,0.67,1100.0
0.00025,10.0,333500000.0,66700000000.0,126.33433230821157,1.5503555088892545e-09,0.67,1100.0
0.00025,10.0,333500000.0,66700000000.0,126.15586530810768,1.5481653892938067e-09,0.67,1100.0
0.00025,10.0,333500000.0,66700000000.0,125.97530725938107,1.5459496086710489e-09,0.67,1100.0
0.00025,10.0,333500000.0,66700000000.0,125.79267648281734,1.5437083918508457e-09,0.67,1100.0
0.00025,10.0,333500000.0,66700000000.0,125.76869015598075,1.5434140353345315e-09,0.67,1100.0
0.00025,10.0,333500000.0,66700000000.0,125.5839962791933,1.541147500465475e-09,0.67,1100.0
0.000375,15.0,750375000.0,66700000000.0,221.10143197068217,9.157464418059824e-09,0.67,1100.0
0.000375,15.0,750375000.0,66700000000.0,221.08543996668413,9.156802069533719e-09,0.67,1100.0
0.000375,15.0,750375000.0,66700000000.0,220.8684093624153,9.147813208545765e-09,0.67,1100.0
0.000375,15.0,750375000.0,66700000000.0,220.64963698240422,9.138752207593626e-09,0.67,1100.0
0.000375,15.0,750375000.0,66700000000.0,220.42913285414366,9.129619481990795e-09,0.67,1100.0
0.000375,15.0,750375000.0,66700000000.0,220.41313893110518,9.128957053982869e-09,0.67,1100.0
0.000375,15.0,750375000.0,66700000000.0,220.19090922316133,9.119752859215819e-09,0.67,1100.0
0.000375,15.0,750375000.0,66700000000.0,219.96696775942786,9.11047776783541e-09,0.67,1100.0
0.000375,15.0,750375000.0,66700000000.0,219.95097575542982,9.109815419309305e-09,0.67,1100.0
0.000375,15.0,750375000.0,66700000000.0,219.72532866281387,9.100469685076596e-09,0.67,1100.0
0.0005,20.0,1334000000.0,66700000000.0,332.5824046384924,3.265120122267236e-08,0.67,1100.0
0.0005,20.0,1334000000.0,66700000000.0,332.3303546183345,3.262645626980783e-08,0.67,1100.0
0.0005,20.0,1334000000.0,66700000000.0,332.3183580366254,3.262527850815265e-08,0.67,1100.0
0.0005,20.0,1334000000.0,66700000000.0,332.0647965920434,3.260038517154227e-08,0.67,1100.0
0.0005,20.0,1334000000.0,66700000000.0,331.8097323883584,3.2575344301901934e-08,0.67,1100.0
0.0005,20.0,1334000000.0,66700000000.0,331.7977368861095,3.257416664622252e-08,0.67,1100.0
0.0005,20.0,1334000000.0,66700000000.0,331.54117426066506,3.254897866936996e-08,0.67,1100.0
0.0005,20.0,1334000000.0,66700000000.0,331.28312185851365,3.252364443403121e-08,0.67,1100.0
0.0005,20.0,1334000000.0,66700000000.0,331.0235861556582,3.249816457598637e-08,0.67,1100.0
0.0005,20.0,1334000000.0,66700000000.0,331.0115895739491,3.2496986814331194e-08,0.67,1100.0
0.000625,25.0,2084375000.0,66700000000.0,458.8019935414741,8.797418044203167e-08,0.67,1100.0
0.000625,25.0,2084375000.0,66700000000.0,458.5195385982141,8.792002038498116e-08,0.67,1100.0
0.000625,25.0,2084375000.0,66700000000.0,458.5099414767749,8.791818015999281e-08,0.67,1100.0
0.000625,25.0,2084375000.0,66700000000.0,458.22613531302204,8.786376100965777e-08,0.67,1100.0
0.000625,25.0,2084375000.0,66700000000.0,457.9409839614787,8.780908392279438e-08,0.67,1100.0
0.000625,25.0,2084375000.0,66700000000.0,457.6544920673447,8.775414979010855e-08,0.67,1100.0
0.000625,25.0,2084375000.0,66700000000.0,457.6448942550508,8.775230943265049e-08,0.67,1100.0
0.000625,25.0,2084375000.0,66700000000.0,457.357065076024,8.769711887879799e-08,0.67,1100.0
0.000625,25.0,2084375000.0,66700000000.0,457.06790462743066,8.764167305720317e-08,0.67,1100.0
0.000625,25.0,2084375000.0,66700000000.0,457.0583075059914,8.763983283221482e-08,0.67,1100.0
0.00075,30.0,3001500000.0,66700000000.0,598.1622253714668,1.9819498213989024e-07,0.67,1100.0
0.00075,30.0,3001500000.0,66700000000.0,597.8525192745207,1.9809236416812725e-07,0.67,1100.0
0.00075,30.0,3001500000.0,66700000000.0,597.5415813258197,1.9798933803478838e-07,0.67,1100.0
0.00075,30.0,3001500000.0,66700000000.0,597.5335828450601,1.979866878193718e-07,0.67,1100.0
0.00075,30.0,3001500000.0,66700000000.0,597.2214156199933,1.9788325437778603e-07,0.67,1100.0
0.00075,30.0,3001500000.0,66700000000.0,596.9080236093222,1.977794151159216e-07,0.67,1100.0
0.00075,30.0,3001500000.0,66700000000.0,596.9000256083227,1.9777676505946868e-07,0.67,1100.0
0.00075,30.0,3001500000.0,66700000000.0,596.5854113801003,1.9767252082822392e-07,0.67,1100.0
0.00075,30.0,3001500000.0,66700000000.0,596.2695794177538,1.9756787311313695e-07,0.67,1100.0
0.00075,30.0,3001500000.0,66700000000.0,584.2667792898178,1.9359086711696654e-07,0.67,1100.0